Workbook

Sheet Resumen
A1: Catálogo de campos clínicos de medicamentos
A2: Extraído del fichero de especificación de carga. Contiene solo los nombres de campo, tipo, obligatoriedad y descripción; sin los valores de ejemplo.
A4: Categorías
A5: Clínico | B5: Dato con impacto en la prescripción, la administración, la seguridad o la monitorización del paciente.
A6: Clave | B6: Identificador o enlace entre entidades. No es clínico pero sin él no se puede montar el modelo.
A7: Técnico | B7: Control del registro (activo/inactivo, nemónico, tamaño de ventana).
A8: Gestión | B8: Compras, almacén, dispensación, facturación, precios. Excluido de las hojas por entidad y recogido aparte.
A10: Recuento por entidad
A11: Entidad | B11: Clínico | C11: Clave | D11: Técnico | E11: Total conservado | F11: Gestión (excluido)
A12: 1. Principio Activo | B12: =COUNTIF('1. Principio Activo'!$B:$B,"Clínico") -> 121 | C12: =COUNTIF('1. Principio Activo'!$B:$B,"Clave") -> 20 | D12: =COUNTIF('1. Principio Activo'!$B:$B,"Técnico") -> 2 | E12: =SUM(B12:D12) -> 143 | F12: 10
A13: 2. Medicamento | B13: =COUNTIF('2. Medicamento'!$B:$B,"Clínico") -> 75 | C13: =COUNTIF('2. Medicamento'!$B:$B,"Clave") -> 32 | D13: =COUNTIF('2. Medicamento'!$B:$B,"Técnico") -> 5 | E13: =SUM(B13:D13) -> 112 | F13: 20
A14: 3. Especialidad | B14: =COUNTIF('3. Especialidad'!$B:$B,"Clínico") -> 19 | C14: =COUNTIF('3. Especialidad'!$B:$B,"Clave") -> 12 | D14: =COUNTIF('3. Especialidad'!$B:$B,"Técnico") -> 2 | E14: =SUM(B14:D14) -> 33 | F14: 103
A15: 4. Transversales | B15: =COUNTIF('4. Transversales'!$B:$B,"Clínico") -> 30 | C15: =COUNTIF('4. Transversales'!$B:$B,"Clave") -> 28 | D15: =COUNTIF('4. Transversales'!$B:$B,"Técnico") -> 7 | E15: =SUM(B15:D15) -> 65 | F15: 0
A17: Nota | B17: Los recuentos de la columna 'Gestión (excluido)' son valores fijos calculados en la extracción; el resto se recalculan con COUNTIF sobre cada hoja.
A21: Responsabilidad
B22: No existe una certificación específica que diga "esta base de datos de medicamentos es de calidad". Lo que existe, y es el modelo de referencia en España, es aplicar una norma de gestión de calidad genérica al proceso de mantenimiento de los datos. El caso de libro es BOT PLUS, del Consejo General de Colegios Oficiales de Farmacéuticos: certifican su sistema de gestión de calidad según ISO 9001 desde 2007, auditado por un organismo externo (Bureau Veritas primero, SGS después). Su modelo es: equipo de farmacéuticos que revisa y homogeneiza el contenido procedente de fuentes oficiales (AEMPS, EMA, consejerías de sanidad), trazabilidad de cada dato hasta su fuente, y auditoría anual del proceso.
B23: La propia AEMPS ya advierte que su información tiene finalidad exclusivamente informativa y carece de validez a efectos legales, y que puede haber errores u omisiones. Cualquier sistema que construyáis encima debería heredar ese mismo disclaimer
A25: Necesidad de interpretación en muchos campos, ejemplo:
A26: Dosis máxima, un extractor automático puede fallar:
A27: 1. Confundir dosis de sobredosis (sección 4.9) con dosis máxima terapéutica (sección 4.2).
A28: 2. Confundir dosis usadas en un estudio clínico (sección 5.1/5.2) con posología aprobada (sección 4.2).
A29: 3. La dosis máxima debe ir relacionada con forma farmacéutica, vía de administración e indicación. En Silicon está en principio activo.

Sheet 1. Principio Activo
A1: PRINCIPIO ACTIVO — campos clínicos
A2: Nivel molécula: lo que no cambia entre marcas. Dosis máximas, vías, frecuencias, consejos y monitorización analítica.
A4: Nº | B4: Categoría | C4: Bloque / Tabla origen | D4: Sección | E4: Sub-bloque | F4: Campo | G4: Tipo | H4: Obl. | I4: Descripción | J4: Notas
A5: Principio activo - General+DMAX
A6: 1 | B6: Clave | C6: Principio activo - General+DMAX | D6: IDENTIFICACIÓN | F6: IDPRINACT | G6: ENTERO | H6: N* | I6: Identificador interno del principio activo.
A7: 2 | B7: Clave | C7: Principio activo - General+DMAX | D7: IDENTIFICACIÓN | F7: IDEXTERNO | G7: CHAR(20) | H7: N* | I7: Identificador del principio activo en la aplicación externa.
A8: 3 | B8: Clave | C8: Principio activo - General+DMAX | D8: IDENTIFICACIÓN | F8: ALTID | G8: CHAR(50) | H8: N* | I8: Identificador alternativo del principio activo.
A9: 4 | B9: Clave | C9: Principio activo - General+DMAX | D9: IDENTIFICACIÓN | F9: DESCRIPCION | G9: CHAR(50) | H9: S* | I9: Descripción del principio activo.
A10: 5 | B10: Clínico | C10: Principio activo - General+DMAX | D10: DETALLES | F10: ATC | G10: CHAR(50) | H10: N | I10: Código ATC.
A11: 6 | B11: Clínico | C11: Principio activo - General+DMAX | D11: DETALLES | F11: RECOMENPRESCRIP | G11: CHAR(4000) | H11: N | I11: Recomendaciones de prescripción.
A12: 7 | B12: Clínico | C12: Principio activo - General+DMAX | D12: DETALLES | F12: CITOSTATICO | G12: CHAR(1) | H12: S | I12: Indica si se trata de un principio activo citostático. Valores posibles: “S”: Sí “N”: No
A13: 8 | B13: Técnico | C13: Principio activo - General+DMAX | D13: DETALLES | F13: ACTIVO | G13: CHAR(1) | H13: S | I13: Estado de la activación del registro. Valores posibles: “S”: Activo “N”: No activo
A14: 9 | B14: Clínico | C14: Principio activo - General+DMAX | D14: DETALLES | E14: GRUPO TERAPÉUTICO - OBLIGATORIO | F14: GT_IDGRUPTERA | G14: ENTERO | H14: N* | I14: Identificador interno del grupo terapéutico.
A15: 10 | B15: Clínico | C15: Principio activo - General+DMAX | D15: DETALLES | E15: GRUPO TERAPÉUTICO - OBLIGATORIO | F15: GT_IDEXTERNO | G15: CHAR(20) | H15: N* | I15: Identificador del grupo terapéutico en la aplicación externa.
A16: 11 | B16: Clínico | C16: Principio activo - General+DMAX | D16: DETALLES | E16: GRUPO TERAPÉUTICO - OBLIGATORIO | F16: GT_CODIGO | G16: CHAR(20) | H16: N* | I16: Código del grupo terapéutico.
A17: 12 | B17: Clínico | C17: Principio activo - General+DMAX | D17: DETALLES | E17: GRUPO TERAPÉUTICO - OBLIGATORIO | F17: GT_ALTID | G17: CHAR(20) | H17: N* | I17: Identificador alternativo del grupo terapéutico.
A18: 13 | B18: Clínico | C18: Principio activo - General+DMAX | D18: DETALLES | E18: UNIDAD - OBLIGATORIO | F18: UN_IDUNIDAD | G18: ENTERO | H18: N* | I18: Identificador interno de la unidad.
A19: 14 | B19: Clínico | C19: Principio activo - General+DMAX | D19: DETALLES | E19: UNIDAD - OBLIGATORIO | F19: UN_IDEXTERNO | G19: CHAR(20) | H19: N* | I19: Identificador de la unidad en la aplicación externa.
A20: 15 | B20: Clínico | C20: Principio activo - General+DMAX | D20: DETALLES | E20: UNIDAD - OBLIGATORIO | F20: UN_CODIGO | G20: CHAR(20) | H20: N* | I20: Código de la unidad.
A21: 16 | B21: Clínico | C21: Principio activo - General+DMAX | D21: DETALLES | E21: UNIDAD - OBLIGATORIO | F21: UN_ALTID | G21: CHAR(20) | H21: N* | I21: Identificador alternativo de la unidad.
A22: 17 | B22: Clínico | C22: Principio activo - General+DMAX | D22: DETALLES | F22: GERDOMAXTOMA | G22: DECIMAL (10, 3) >=0 | H22: N | I22: Dosis máxima por toma y m2 de superficie corporal para pacientes de grupo poblacional geriátrico, expresada en las unidades indicadas en UNIDAD.
A23: 18 | B23: Clínico | C23: Principio activo - General+DMAX | D23: DETALLES | F23: GERDOMAXTOMAM2 | G23: DECIMAL (10, 3) >=0 | H23: N | I23: Dosis máxima por toma y m2 de superficie corporal para pacientes de grupo poblacional geriátrico, expresada en las unidades indicadas en UNIDAD.
A24: 19 | B24: Clínico | C24: Principio activo - General+DMAX | D24: DETALLES | F24: GERDOMAXTOMAKG | G24: DECIMAL (10, 3) >=0 | H24: N | I24: Dosis máxima por toma y kilo para pacientes de grupo poblacional geriátrico, expresada en las unidades indicadas en UNIDAD.
A25: 20 | B25: Clínico | C25: Principio activo - General+DMAX | D25: DETALLES | F25: GERDOMAXDIA | G25: DECIMAL (10, 3) >=0 | H25: N | I25: Dosis máxima por día para pacientes de grupo poblacional geriátrico, expresada en las unidades indicadas en UNIDAD.
A26: 21 | B26: Clínico | C26: Principio activo - General+DMAX | D26: DETALLES | F26: GERDOMAXDIAM2 | G26: DECIMAL (10, 3) >=0 | H26: N | I26: Dosis máxima por día y m2 de superficie corporal para pacientes de grupo poblacional geriátrico, expresada en las unidades indicadas en UNIDAD.
A27: 22 | B27: Clínico | C27: Principio activo - General+DMAX | D27: DETALLES | F27: GERDOMAXDIAKG | G27: DECIMAL (10, 3) >=0 | H27: N | I27: Dosis máxima por día y kilo para pacientes de grupo poblacional geriátrico, expresada en las unidades indicadas en UNIDAD.
A28: 23 | B28: Clínico | C28: Principio activo - General+DMAX | D28: DETALLES | F28: GERNDIAS | G28: ENTERO >=0 | H28: N | I28: Periodo de N días que define para pacientes de grupo poblacional geriátrico la dosis máxima en un periodo (campo siguiente)
A29: 24 | B29: Clínico | C29: Principio activo - General+DMAX | D29: DETALLES | F29: GERDOMAXNDIAS | G29: DECIMAL (10, 3) >=0 | H29: N | I29: Dosis máxima por periodo de N días para pacientes de grupo poblacional geriátrico, expresada en las unidades indicadas en UNIDAD.
A30: 25 | B30: Clínico | C30: Principio activo - General+DMAX | D30: DETALLES | F30: GERNDIASM2 | G30: ENTERO >=0 | H30: N | I30: Periodo de N días que define para pacientes de grupo poblacional geriátrico la dosis máxima por m2 de superficie corporal en un periodo (campo siguiente)
A31: 26 | B31: Clínico | C31: Principio activo - General+DMAX | D31: DETALLES | F31: GERDOMAXNDIASM2 | G31: DECIMAL (10, 3) >=0 | H31: N | I31: Dosis máxima por m2 de superficie corporal en un periodo de N días para pacientes de grupo poblacional geriátrico, expresada en las unidades indicadas en UNIDAD.
A32: 27 | B32: Clínico | C32: Principio activo - General+DMAX | D32: DETALLES | F32: GERNDIASKG | G32: ENTERO >=0 | H32: N | I32: Periodo de N días que define para pacientes de grupo poblacional geriátrico la dosis máxima por kilo en un periodo (campo siguiente)
A33: 28 | B33: Clínico | C33: Principio activo - General+DMAX | D33: DETALLES | F33: GERDOMAXNDIASKG | G33: DECIMAL (10, 3) >=0 | H33: N | I33: Dosis máxima por kilo en un periodo de N días para pacientes de grupo poblacional geriátrico, expresada en las unidades indicadas en UNIDAD.
... A96: 91 | B96: Clínico | C96: Principio activo - General+DMAX | D96: DETALLES | F96: NEODOMAXACUMULADAKG | G96: DECIMAL (10, 3) >=0 | H96: N | I96: Dosis máxima acumulada por paciente y kilo para pacientes de grupo poblacional neonato, expresada en las unidades indicadas en UNIDAD.
A97: Principio activo - Frecuencias
A98: 92 | B98: Clave | C98: Principio activo - Frecuencias | D98: IDENTIFICACIÓN | E98: PRINCIPIO ACTIVO | F98: IDPRINACT | G98: ENTERO | H98: N* | I98: Identificador interno del principio activo.
A99: 93 | B99: Clave | C99: Principio activo - Frecuencias | D99: IDENTIFICACIÓN | E99: PRINCIPIO ACTIVO | F99: IDEXTERNO | G99: CHAR(20) | H99: N* | I99: Identificador del principio activo en la aplicación externa.
A100: 94 | B100: Clave | C100: Principio activo - Frecuencias | D100: IDENTIFICACIÓN | E100: PRINCIPIO ACTIVO | F100: ALTID | G100: CHAR(50) | H100: N* | I100: Identificador alternativo del principio activo.
A101: 95 | B101: Clave | C101: Principio activo - Frecuencias | D101: IDENTIFICACIÓN | E101: PRINCIPIO ACTIVO | F101: DESCRIPCION | G101: CHAR(50) | H101: S* | I101: Descripción del principio activo.
A102: 96 | B102: Clínico | C102: Principio activo - Frecuencias | D102: IDENTIFICACIÓN | E102: FRECUENCIA | F102: FQ_IDFRECUENCIA | G102: ENTERO | H102: N* | I102: Identificador interno de la frecuencia.
A103: 97 | B103: Clínico | C103: Principio activo - Frecuencias | D103: IDENTIFICACIÓN | E103: FRECUENCIA | F103: FQ_IDEXTERNO | G103: CHAR(20) | H103: N* | I103: Identificador de la frecuencia en la aplicación externa.
...

Sheet 2. Medicamento
A1: MEDICAMENTO — campos clínicos
A2: Nivel producto prescribible (molécula + dosis + forma). Composición, indicaciones, vías, frecuencias y pauta por defecto por grupo poblacional.
A4: Nº | B4: Categoría | C4: Bloque / Tabla origen | D4: Sección | E4: Sub-bloque | F4: Campo | G4: Tipo | H4: Obl. | I4: Descripción | J4: Notas
A5: Medicamento - General
A6: 1 | B6: Clave | C6: Medicamento - General | D6: IDENTIFICACIÓN | F6: IDMEDICAME | G6: ENTERO | H6: N* | I6: Identificador interno del medicamento.
A7: 2 | B7: Clave | C7: Medicamento - General | D7: IDENTIFICACIÓN | F7: IDEXTERNO | G7: CHAR(20) | H7: N* | I7: Identificador del medicamento en la aplicación externa.
A8: 3 | B8: Clave | C8: Medicamento - General | D8: IDENTIFICACIÓN | F8: ALTID | G8: CHAR(50) | H8: N* | I8: Identificador alternativo del medicamento.
A9: 4 | B9: Clave | C9: Medicamento - General | D9: IDENTIFICACIÓN | F9: DESCRIPCION | G9: CHAR(100) | H9: S* | I9: Descripción del medicamento.
A10: 5 | B10: Técnico | C10: Medicamento - General | D10: DETALLES | F10: NEMONICO | G10: CHAR(20) | H10: N | I10: Nemónico del medicamento
A11: 6 | B11: Clínico | C11: Medicamento - General | D11: DETALLES | F11: ADMINISTRACION | G11: CHAR(1) | H11: S | I11: Tipo de administración del medicamento. Valores posibles: “F”: Fluidoterapia “M”: Inmediata “R”: Transdérmica
A12: 7 | B12: Clínico | C12: Medicamento - General | D12: DETALLES | F12: TASALIBERACION | G12: DECIMAL (10, 3) > 0 | H12: N | I12: Tasa de liberación de PA en el caso de tratarse de un medicamento transdérmico expresado en unidades de medicamento. Obligatorio si el ADMINISTRACION = “R”.
A13: 8 | B13: Clínico | C13: Medicamento - General | D13: DETALLES | F13: TASALIBERACIONHORAS | G13: ENTERO >= 1 y <= 999 | H13: N | I13: Número de horas de la tasa de liberación en caso de administración de medicamento transdérmico. Obligatorio si el ADMINISTRACION = “R”.
A14: 9 | B14: Clínico | C14: Medicamento - General | D14: DETALLES | F14: VOLUMEN | G14: DECIMAL (10, 3) > 0 | H14: N | I14: Volumen del medicamento para administración por fluidoterapia, expresado en ml. Obligatorio si el ADMINISTRACION = “F”.
A15: 10 | B15: Clínico | C15: Medicamento - General | D15: DETALLES | E15: FORMA FARMACÉUTICA - OBLIGATORIO | F15: FF_FORMAFAR | G15: ENTERO | H15: N* | I15: Identificador interno de la forma farmacéutica.
A16: 11 | B16: Clínico | C16: Medicamento - General | D16: DETALLES | E16: FORMA FARMACÉUTICA - OBLIGATORIO | F16: FF_IDEXTERNO | G16: CHAR(20) | H16: N* | I16: Identificador de la forma farmacéutica en la aplicación externa.
A17: 12 | B17: Clínico | C17: Medicamento - General | D17: DETALLES | E17: FORMA FARMACÉUTICA - OBLIGATORIO | F17: FF_CODIGO | G17: CHAR(20) | H17: N* | I17: Código de la forma farmacéutica.
A18: 13 | B18: Clínico | C18: Medicamento - General | D18: DETALLES | E18: FORMA FARMACÉUTICA - OBLIGATORIO | F18: FF_ALTID | G18: CHAR(20) | H18: N* | I18: Identificador alternativo de la forma farmacéutica.
A19: 14 | B19: Clínico | C19: Medicamento - General | D19: DETALLES | E19: GRUPO TERAPÉUTICO - OBLIGATORIO | F19: GT_IDGRUPTERA | G19: ENTERO | H19: N* | I19: Identificador interno del grupo terapéutico.
A20: 15 | B20: Clínico | C20: Medicamento - General | D20: DETALLES | E20: GRUPO TERAPÉUTICO - OBLIGATORIO | F20: GT_IDEXTERNO | G20: CHAR(20) | H20: N* | I20: Identificador del grupo terapéutico en la aplicación externa.
A21: 16 | B21: Clínico | C21: Medicamento - General | D21: DETALLES | E21: GRUPO TERAPÉUTICO - OBLIGATORIO | F21: GT_CODIGO | G21: CHAR(20) | H21: N* | I21: Código del grupo terapéutico.
A22: 17 | B22: Clínico | C22: Medicamento - General | D22: DETALLES | E22: GRUPO TERAPÉUTICO - OBLIGATORIO | F22: GT_ALTID | G22: CHAR(20) | H22: N* | I22: Identificador alternativo del grupo terapéutico.
A23: 18 | B23: Clínico | C23: Medicamento - General | D23: DETALLES | F23: DOSIS | G23: DECIMAL(10, 3) > 0 | H23: S | I23: Dosis del medicamento, expresada en unidades de dosis
A24: 19 | B24: Clínico | C24: Medicamento - General | D24: DETALLES | E24: UNIDAD DE DOSIS - OBLIGATORIO | F24: UD_IDUNIDAD | G24: ENTERO | H24: N* | I24: Identificador interno de la unidad de dosis.
A25: 20 | B25: Clínico | C25: Medicamento - General | D25: DETALLES | E25: UNIDAD DE DOSIS - OBLIGATORIO | F25: UD_IDEXTERNO | G25: CHAR(20) | H25: N* | I25: Identificador de la unidad de dosis en la aplicación externa.
A26: 21 | B26: Clínico | C26: Medicamento - General | D26: DETALLES | E26: UNIDAD DE DOSIS - OBLIGATORIO | F26: UD_CODIGO | G26: CHAR(20) | H26: N* | I26: Código de la unidad de dosis.
A27: 22 | B27: Clínico | C27: Medicamento - General | D27: DETALLES | E27: UNIDAD DE DOSIS - OBLIGATORIO | F27: UD_ALTID | G27: CHAR(20) | H27: N* | I27: Identificador alternativo de la unidad de dosis.
A28: 23 | B28: Clínico | C28: Medicamento - General | D28: DETALLES | F28: DOSISADMIN | G28: DECIMAL (10, 3) > 0 | H28: S | I28: Dosis de administración, expresada en unidades de administración.
A29: 24 | B29: Clínico | C29: Medicamento - General | D29: DETALLES | E29: UNIDAD DE DOSIS - OBLIGATORIO | F29: UDA_IDUNIDAD | G29: ENTERO | H29: N* | I29: Identificador interno de la unidad de dosis de administración.
A30: 25 | B30: Clínico | C30: Medicamento - General | D30: DETALLES | E30: UNIDAD DE DOSIS - OBLIGATORIO | F30: UDA_IDEXTERNO | G30: CHAR(20) | H30: N* | I30: Identificador de la unidad de dosis de administración en la aplicación externa.
A31: 26 | B31: Clínico | C31: Medicamento - General | D31: DETALLES | E31: UNIDAD DE DOSIS - OBLIGATORIO | F31: UDA_CODIGO | G31: CHAR(20) | H31: N* | I31: Código de la unidad de dosis de administración.
A32: 27 | B32: Clínico | C32: Medicamento - General | D32: DETALLES | E32: UNIDAD DE DOSIS - OBLIGATORIO | F32: UDA_ALTID | G32: CHAR(20) | H32: N* | I32: Identificador alternativo de la unidad de dosis de administración.
A33: 28 | B33: Clínico | C33: Medicamento - General | D33: DETALLES | F33: NOADMINSOLO | G33: CHAR(1) | H33: S | I33: Indica si el medicamento no se puede administrar solo. Valores posibles: "S": No es posible administrarlo solo "N": Es posible administrarlo solo. | J33: Clínico: obliga a dilución / vehículo.
A34: 29 | B34: Clínico | C34: Medicamento - General | D34: DETALLES | F34: FUNCRENA | G34: CHAR(1) | H34: S | I34: Indica si el medicamento tiene función renal. Valores posibles: "S": Sí. "N": No.
A35: 30 | B35: Clínico | C35: Medicamento - General | D35: DETALLES | F35: FUNCHEPA | G35: CHAR(1) | H35: S | I35: Indica si el medicamento tiene función hepática. Valores posibles: "S": Sí. "N": No.
A36: 31 | B36: Clínico | C36: Medicamento - General | D36: DETALLES | F36: STOPORDER | G36: ENTERO >= 0 | H36: S | I36: Stop order, expresado en días | J36: Clínico: parada automática del tratamiento a los N días.
A37: 32 | B37: Clínico | C37: Medicamento - General | D37: DETALLES | F37: INDICADOGERIATRICO | G37: CHAR(1) | H37: S | I37: Indica que el medicamento está disponible para pacientes del grupo poblacional geriátrico. Valores posibles: "S": Sí. "N": No.
A38: 33 | B38: Clínico | C38: Medicamento - General | D38: DETALLES | F38: INDICADOADULTO | G38: CHAR(1) | H38: S | I38: Indica que el medicamento está disponible para pacientes del grupo poblacional adulto. Valores posibles: "S": Sí. "N": No.
A39: 34 | B39: Clínico | C39: Medicamento - General | D39: DETALLES | F39: INDICADOPEDIATRICO | G39: CHAR(1) | H39: S | I39: Indica que el medicamento está disponible para pacientes del grupo poblacional pediátrico. Valores posibles: "S": Sí. "N": No.
A40: 35 | B40: Clínico | C40: Medicamento - General | D40: DETALLES | F40: INDICADOLACTANTE | G40: CHAR(1) | H40: S | I40: Indica que el medicamento está disponible para pacientes del grupo poblacional lactante. Valores posibles: "S": Sí. "N": No.
A41: 36 | B41: Clínico | C41: Medicamento - General | D41: DETALLES | F41: INDICADONEONATO | G41: CHAR(1) | H41: S | I41: Indica que el medicamento está disponible para pacientes del grupo poblacional neonato. Valores posibles: "S": Sí. "N": No.
...

Sheet 3. Especialidad
A1: ESPECIALIDAD — campos clínicos
A2: Nivel envase concreto de laboratorio. Solo se conserva lo que llega al prescriptor o afecta a la administración; el resto es compras/almacén.
A4: Nº | B4: Categoría | C4: Bloque / Tabla origen | D4: Sección | E4: Sub-bloque | F4: Campo | G4: Tipo | H4: Obl. | I4: Descripción | J4: Notas
A5: Especialidad - General
A6: 1 | B6: Clave | C6: Especialidad - General | D6: IDENTIFICACIÓN | F6: IDESPECIALIDAD | G6: ENTERO | H6: N* | I6: Identificador interno de la especialidad.
A7: 2 | B7: Clave | C7: Especialidad - General | D7: IDENTIFICACIÓN | F7: IDEXTERNO | G7: CHAR(20) | H7: N* | I7: Identificador de la especialidad en la aplicación externa.
A8: 3 | B8: Clave | C8: Especialidad - General | D8: IDENTIFICACIÓN | F8: CODIGONACIONAL | G8: CHAR(20) | H8: N* | I8: Código nacional de la especialidad.
A9: 4 | B9: Clave | C9: Especialidad - General | D9: IDENTIFICACIÓN | F9: ALTIDPRES | G9: CHAR(20) | H9: N* | I9: Identificador alternativo de prescripción de la especialidad.
A10: 5 | B10: Clínico | C10: Especialidad - General | D10: DETALLES | F10: DESCRIPCIONPRESCRIP | G10: CHAR(100) | H10: S | I10: Descripción de prescripción de la especialidad.
A11: 6 | B11: Técnico | C11: Especialidad - General | D11: DETALLES | F11: NEMONICOPRESCRIP | G11: CHAR(20) | H11: N | I11: Nemónico de prescripción de la especialidad.
A12: 7 | B12: Clave | C12: Especialidad - General | D12: DETALLES | E12: MEDICAMENTO - OBLIGATORIO | F12: ME_IDMEDICAME | G12: ENTERO | H12: N* | I12: Identificador interno del medicamento asociado a la especialidad.
A13: 8 | B13: Clave | C13: Especialidad - General | D13: DETALLES | E13: MEDICAMENTO - OBLIGATORIO | F13: ME_IDEXTERNO | G13: CHAR(20) | H13: N* | I13: Identificador del medicamento en la aplicación externa.
A14: 9 | B14: Clave | C14: Especialidad - General | D14: DETALLES | E14: MEDICAMENTO - OBLIGATORIO | F14: ME_DESCRIPCION | G14: CHAR(20) | H14: N* | I14: Descripción del medicamento asociado a la especialidad.
A15: 10 | B15: Clave | C15: Especialidad - General | D15: DETALLES | E15: MEDICAMENTO - OBLIGATORIO | F15: ME_ALTID | G15: CHAR(20) | H15: N* | I15: Identificador alternativo del medicamento asociado a la especialidad.
A16: 11 | B16: Clínico | C16: Especialidad - General | D16: DETALLES | E16: TIPO DE ESPECIALIDAD - OPCIONAL | F16: TEF_IDTIPESPEC | G16: ENTERO | H16: N* | I16: Identificador interno del tipo de especialidad. | J16: Revisable según cómo se use el tipo de especialidad en vuestro maestro.
A17: 12 | B17: Clínico | C17: Especialidad - General | D17: DETALLES | E17: TIPO DE ESPECIALIDAD - OPCIONAL | F17: TEF_IDEXTERNO | G17: CHAR(20) | H17: N* | I17: Identificador del tipo de especialidad en la aplicación externa.
A18: 13 | B18: Clínico | C18: Especialidad - General | D18: DETALLES | E18: TIPO DE ESPECIALIDAD - OPCIONAL | F18: TEF_CODIGO | G18: CHAR(20) | H18: N* | I18: Código del tipo de especialidad.
A19: 14 | B19: Clínico | C19: Especialidad - General | D19: DETALLES | E19: TIPO DE ESPECIALIDAD - OPCIONAL | F19: TEF_ALTID | G19: CHAR(20) | H19: N* | I19: Identificador alternativo del tipo de especialidad.
A20: 15 | B20: Clínico | C20: Especialidad - General | D20: DETALLES | F20: EXTRANJERO | G20: CHAR(1) | H20: S | I20: Indica si la especialidad es extranjera. Valores posibles: “S”: Sí. “N”: No. | J20: Clínico/regulatorio: medicamento extranjero, condiciona la prescripción.
A21: 16 | B21: Clínico | C21: Especialidad - General | D21: DETALLES | F21: ENSAYOCLINICO | G21: CHAR(1) | H21: S | I21: Indica si la especialidad es de ensayo clínico. Valores posibles: “S”: Sí. “N”: No. | J21: Clínico/regulatorio: producto en ensayo clínico.
A22: 17 | B22: Clínico | C22: Especialidad - General | D22: DETALLES | F22: MULTIDOSIS | G22: CHAR(1) | H22: S | I22: Indica si la especialidad es multidosis. Valores posibles: “S”: Sí. “N”: No. | J22: Clínico: condiciona estabilidad en uso y reutilización del envase.
A23: 18 | B23: Clínico | C23: Especialidad - General | D23: DETALLES | F23: PERIODOVALIDEZ | G23: ENTERO >0 | H23: N | I23: Periodo de validez de la especialidad una vez abierto el envase. | J23: Clínico: caducidad una vez abierto el envase.
A24: 19 | B24: Clínico | C24: Especialidad - General | D24: DETALLES | F24: PERIODOVALIDEZUNI | G24: CHAR(1) | H24: N | I24: Unidades del periodo de validez: “H”: Horas. “D”: Días. “S”: Semanas. “M”: Meses “A”: Años. | J24: Clínico: unidad del periodo de validez tras apertura.
A25: 20 | B25: Técnico | C25: Especialidad - General | D25: DETALLES | F25: ACTIVO | G25: CHAR(1) | H25: S | I25: Estado de la activación del registro. Valores posibles: “S”: Activo “N”: No activo
A26: Especialidad - Excipientes
A27: 21 | B27: Clave | C27: Especialidad - Excipientes | D27: IDENTIFICACIÓN | E27: ESPECIALIDAD | F27: IDESPECIALIDAD | G27: ENTERO | H27: N* | I27: Identificador interno de la especialidad.
A28: 22 | B28: Clave | C28: Especialidad - Excipientes | D28: IDENTIFICACIÓN | E28: ESPECIALIDAD | F28: IDEXTERNO | G28: CHAR(20) | H28: N* | I28: Identificador de la especialidad en la aplicación externa.
A29: 23 | B29: Clave | C29: Especialidad - Excipientes | D29: IDENTIFICACIÓN | E29: ESPECIALIDAD | F29: CODIGONACIONAL | G29: CHAR(20) | H29: N* | I29: Código nacional de la especialidad.
A30: 24 | B30: Clave | C30: Especialidad - Excipientes | D30: IDENTIFICACIÓN | E30: ESPECIALIDAD | F30: ALTIDPRES | G30: CHAR(20) | H30: N* | I30: Identificador alternativo de prescripción de la especialidad.
A31: 25 | B31: Clínico | C31: Especialidad - Excipientes | D31: IDENTIFICACIÓN | E31: EXCIPIENTE | F31: EX_IDEXCIPIENTE | G31: ENTERO | H31: N* | I31: Identificador interno del excipiente. | J31: Clave clínica: soporte de alergias e intolerancias a excipientes.
A32: 26 | B32: Clínico | C32: Especialidad - Excipientes | D32: IDENTIFICACIÓN | E32: EXCIPIENTE | F32: EX_IDEXTERNO | G32: CHAR(20) | H32: N* | I32: Identificador del excipiente en la aplicación externa.
A33: 27 | B33: Clínico | C33: Especialidad - Excipientes | D33: IDENTIFICACIÓN | E33: EXCIPIENTE | F33: EX_ALTID | G33: CHAR(20) | H33: N* | I33: Identificador alternativo del excipiente.
A34: 28 | B34: Clínico | C34: Especialidad - Excipientes | D34: IDENTIFICACIÓN | E34: EXCIPIENTE | F34: EX_DESCRIPCION | G34: CHAR(20) | H34: N* | I34: Descripción del excipiente.
A35: 29 | B35: Clínico | C35: Especialidad - Excipientes | D35: IDENTIFICACIÓN | F35: CANTIDAD | G35: DECIMAL (10, 3) > 0 | H35: S | I35: Cantidad de excipiente presente en la composición de la especialidad.
A36: 30 | B36: Clínico | C36: Especialidad - Excipientes | D36: IDENTIFICACIÓN | E36: UNIDAD - OBLIGATORIO - DEBE COINCIDIR CON LA UNIDAD DEL EXCIPIENTE | F36: UN_IDUNIDAD | G36: ENTERO | H36: N* | I36: Identificador interno de la unidad.
A37: 31 | B37: Clínico | C37: Especialidad - Excipientes | D37: IDENTIFICACIÓN | E37: UNIDAD - OBLIGATORIO - DEBE COINCIDIR CON LA UNIDAD DEL EXCIPIENTE | F37: UN_IDEXTERNO | G37: CHAR(20) | H37: N* | I37: Identificador de la unidad en la aplicación externa.
A38: 32 | B38: Clínico | C38: Especialidad - Excipientes | D38: IDENTIFICACIÓN | E38: UNIDAD - OBLIGATORIO - DEBE COINCIDIR CON LA UNIDAD DEL EXCIPIENTE | F38: UN_CODIGO | G38: CHAR(20) | H38: N* | I38: Código de la unidad.
A39: 33 | B39: Clínico | C39: Especialidad - Excipientes | D39: IDENTIFICACIÓN | E39: UNIDAD - OBLIGATORIO - DEBE COINCIDIR CON LA UNIDAD DEL EXCIPIENTE | F39: UN_ALTID | G39: CHAR(20) | H39: N* | I39: Identificador alternativo de la unidad.

Sheet Eval. AEMPS (Especialidad)
A1: ESPECIALIDAD — ¿se puede completar desde AEMPS?
A2: Evaluación campo a campo de los 33 campos conservados en la hoja Especialidad frente a dos fuentes distintas: el TEXTO de la ficha técnica (secciones 1-10) y el METADATO estructurado de CIMA (API REST v1.23, cima.aemps.es/cima/rest). No son lo mismo y la diferencia decide el proyecto.
A4: Nº | B4: Bloque | C4: Campo | D4: Cat. | E4: ¿Completable desde AEMPS? | F4: Fuente concreta | G4: Esfuerzo | H4: Observación / riesgo
A5: 1 | B5: General | C5: IDESPECIALIDAD | D5: Clave | E5: No | F5: — | G5: — | H5: Identificador interno de vuestro sistema. AEMPS no interviene.
A6: 2 | B6: General | C6: IDEXTERNO | D6: Clave | E6: Parcial – derivado | F6: CIMA: presentaciones[].cn | G6: Bajo | H6: Si adoptáis el CN como identificador externo, queda resuelto y trazable contra CIMA.
A7: 3 | B7: General | C7: CODIGONACIONAL | D7: Clave | E7: Sí – directo | F7: CIMA: presentaciones[].cn | G7: Bajo | H7: NO está en el texto de la ficha técnica: es metadato de CIMA / Nomenclátor.
A8: 4 | B8: General | C8: ALTIDPRES | D8: Clave | E8: Parcial – derivado | F8: CN | G8: Bajo | H8: Convención propia; lo habitual es reutilizar el CN.
A9: 5 | B9: General | C9: DESCRIPCIONPRESCRIP | D9: Clínico | E9: Sí – directo | F9: CIMA: presentaciones[].nombre o medicamento.nombre | G9: Medio | H9: El nombre de presentación incluye el formato del envase ('…, 28 cápsulas'). Decidir si el prescriptor lo ve. Riesgo de truncado en CHAR(100) en biológicos y combinaciones.
A10: 6 | B10: General | C10: NEMONICOPRESCRIP | D10: Técnico | E10: No | F10: — | G10: — | H10: Se genera con vuestras reglas de abreviatura.
A11: 7 | B11: General | C11: ME_IDMEDICAME | D11: Clave | E11: No | F11: — | G11: — | H11: Enlace a vuestra entidad Medicamento; ID interno.
A12: 8 | B12: General | C12: ME_IDEXTERNO | D12: Clave | E12: Parcial – derivado | F12: CIMA: nregistro | G12: Bajo | H12: El nº de registro es el pivote natural: agrupa todas las presentaciones de un mismo medicamento.
A13: 9 | B13: General | C13: ME_DESCRIPCION | D13: Clave | E13: Parcial – derivado | F13: CIMA: nombre + dosis + formaFarmaceutica | G13: Medio | H13: Reconstruible, pero ojo: el campo es CHAR(20) en el origen y no cabe una descripción real. Revisar la especificación.
A14: 10 | B14: General | C14: ME_ALTID | D14: Clave | E14: Parcial – derivado | F14: CIMA: nregistro o VMP | G14: Bajo | H14: El código VMP (SNOMED) es buen candidato si buscáis un id estándar.
A15: 11 | B15: General | C15: TEF_IDTIPESPEC | D15: Clínico | E15: No | F15: — | G15: — | H15: ID de vuestro maestro de tipos.
A16: 12 | B16: General | C16: TEF_IDEXTERNO | D16: Clínico | E16: Parcial – derivado | F16: — | G16: Bajo | H16: Depende del maestro.
... A37: 33 | B37: Excipientes | C37: UN_ALTID | D37: Clínico | E37: Parcial – derivado | F37: — | G37: Bajo | H37: Depende del maestro.
B39: Recuento
B40: Sí – directo | C40: =COUNTIF($E$5:$E$37,B40) -> 8
B41: Sí – texto FT | C41: =COUNTIF($E$5:$E$37,B41) -> 3
B42: Parcial – derivado | C42: =COUNTIF($E$5:$E$37,B42) -> 14
B43: No | C43: =COUNTIF($E$5:$E$37,B43) -> 8
B44: TOTAL | C44: =SUM(C40:C43) -> 33
B46: Cuatro cosas que conviene decidir antes de empezar
B47: Desajuste de granularidad | C47: La ficha técnica y los excipientes son por Nº DE REGISTRO (medicamento autorizado); vuestra Especialidad es por CÓDIGO NACIONAL (presentación). Un registro tiene N presentaciones, así que todo lo heredado de la FT se replica idéntico en todas ellas. Ejemplo real: nregistro 51347 (Aspirina C) → 2 códigos nacionales, una sola ficha técnica.
B48: La lista de excipientes de CIMA está incompleta | C48: CIMA expone solo los excipientes de declaración obligatoria, no la sección 6.1 completa. Se nota en el campo 'orden', que salta: en el ejemplo anterior devuelve 3 excipientes con orden 1, 2 y 9. Para la lista íntegra hay que parsear el texto de la 6.1, que además es CUALITATIVA (sin cantidades).
B49: Pero la cobertura funcional es mejor que la nominal | C49: Los excipientes de declaración obligatoria son precisamente los que generan alerta clínica (lactosa, sodio, aspartamo, alcohol bencílico, sulfitos…). Para alimentar alergias e intolerancias, lo que da CIMA es suficiente; la sección 6.1 completa aportaría sobre todo ruido.
B50: El documento de ficha técnica aporta muy poco a esta hoja | C50: De los 33 campos, solo 3 salen del texto (validez tras apertura y multidosis, secciones 6.3 y 6.5). Todo lo demás que sí es automatizable viene del metadato estructurado de CIMA, no del PDF. Si el plan era leer fichas técnicas, conviene invertirlo: API primero, texto solo para esos tres.
B51: Mantenimiento | C51: El endpoint registroCambios devuelve altas, bajas y modificaciones desde una fecha, marcando si el cambio afectó a la ficha técnica, al estado o a la comercialización. Es lo que permite que esto no sea una carga única.

Sheet Fuente recomendada (Esp.)
A1: ESPECIALIDAD — fuente de origen recomendada, campo a campo
A2: Misma comprobación que la hoja anterior, pero sin dar por supuesta la fuente. Conclusión: para esta entidad la fuente correcta NO es una base de datos externa — es vuestro propio catálogo. Lo externo cubre un bloque y solo uno: los excipientes.
A4: Nº | B4: Bloque | C4: Campo | D4: Fuente recomendada | E4: Fuente de contraste | F4: Cob. | G4: Por qué esa fuente
A5: 1 | B5: General | C5: IDESPECIALIDAD | D5: Catálogo actual | E5: — | F5: 100% | G5: Es vuestra clave primaria. Migrarla, no reinventarla: cualquier histórico de prescripción, consumo o trazabilidad cuelga de ella.
A6: 2 | B6: General | C6: IDEXTERNO | D6: Catálogo actual | E6: — | F6: 100% | G6: Identificador del sistema de origen. Es literalmente el campo que existe para no perder la trazabilidad de la migración.
A7: 3 | B7: General | C7: CODIGONACIONAL | D7: Catálogo actual | E7: CIMA: presentaciones[].cn | F7: 100% | G7: Ya lo tenéis, y filtrado a lo que realmente manejáis. CIMA sirve para VALIDARLO, no para poblarlo: si cargáis desde CIMA os traéis las ~23.000 presentaciones de España en vez de vuestro catálogo.
A8: 4 | B8: General | C8: ALTIDPRES | D8: Catálogo actual | E8: — | F8: 100% | G8: Convención propia ya establecida.
A9: 5 | B9: General | C9: DESCRIPCIONPRESCRIP | D9: Catálogo actual | E9: CIMA: nombre | F9: 95% | G9: ARGUMENTO DE SEGURIDAD: vuestros prescriptores reconocen las descripciones actuales. Sustituirlas en bloque por las de CIMA introduce riesgo de selección errónea el primer día. Migrar y normalizar después.
A10: 6 | B10: General | C10: NEMONICOPRESCRIP | D10: Catálogo actual | E10: — | F10: 100% | G10: Regla propia de abreviatura ya en uso.
A11: 7 | B11: General | C11: ME_IDMEDICAME | D11: Catálogo actual | E11: — | F11: 100% | G11: La agrupación especialidad→medicamento ya existe en vuestro catálogo; es una decisión de modelo, no un dato externo.
A12: 8 | B12: General | C12: ME_IDEXTERNO | D12: Catálogo actual | E12: — | F12: 100% | G12: Enlace del sistema de origen.
A13: 9 | B13: General | C13: ME_DESCRIPCION | D13: Catálogo actual | E13: — | F13: 100% | G13: Ídem. Revisar antes el CHAR(20) de la especificación.
A14: 10 | B14: General | C14: ME_ALTID | D14: Catálogo actual | E14: CIMA: nregistro / VMP | F14: 100% | G14: Si queréis un id estándar para el futuro, el VMP de CIMA es el candidato.
A15: 11 | B15: General | C15: TEF_IDTIPESPEC | D15: Catálogo actual | E15: — | F15: 100% | G15: Maestro propio.
A16: 12 | B16: General | C16: TEF_IDEXTERNO | D16: Catálogo actual | E16: — | F16: 100% | G16: Maestro propio.
... A37: 33 | B37: Excipientes | C37: UN_ALTID | D37: Catálogo actual | E37: — | F37: 100% | G37: Maestro propio.
B39: Reparto de los 33 campos
B40: Catálogo actual | C40: =COUNTIF($D$5:$D$37,B40) -> 26
B41: CIMA (API) | C41: =COUNTIF($D$5:$D$37,B41) -> 4
B42: Curación manual | C42: =COUNTIF($D$5:$D$37,B42) -> 3
B43: Base comercial | C43: =COUNTIF($D$5:$D$37,B43) -> 0
B44: TOTAL | C44: =SUM(C40:C43) -> 33
B46: Fuentes evaluadas
B47: Fuente | C47: Lo que aporta | D47: Lo que no cubre | E47: Veredicto para esta hoja
B48: Vuestro catálogo actual | C48: Todos los identificadores internos, los enlaces entre entidades, las descripciones que el prescriptor ya reconoce, y el filtro esencial: solo lo que realmente manejáis. | D48: No tiene excipientes codificados (casi ningún catálogo hospitalario los tiene) ni validez tras apertura. | E48: FUENTE PRIMARIA de esta hoja.
B49: CIMA – API REST (AEMPS) | C49: Gratuita, oficial, JSON, con excipientes de declaración obligatoria cuantificados e id estable, y endpoint registroCambios para mantenimiento. | D49: Cubre toda España, no vuestro catálogo. No codifica validez tras apertura ni multidosis. No tiene extranjeros ni ensayos. | E49: COMPLEMENTO para el bloque de excipientes y para el mantenimiento del estado.
B50: BOT PLUS integración (CGCOF) | C50: Servicios web pensados para integrarse en sistemas hospitalarios. Cubre uso hospitalario, envases clínicos y extranjeros. Aporta interacciones, enfermedades y mensajes de advertencia ya codificados. | D50: Licencia de pago. Para ESTA hoja aporta poco sobre CIMA: la composición codificada son los mismos excipientes de declaración obligatoria (Circular 1/2018) extraídos de las mismas fichas técnicas. | E50: NO se justifica por la hoja Especialidad. Se justifica por Transversales y Principio Activo.
B51: Texto de la ficha técnica (PDF/HTML) | C51: Única fuente de la validez tras apertura (6.3) y de las pistas de multidosis (6.5). | D51: Prosa libre, por nº de registro y no por CN. Parsearla a escala es caro y frágil. | E51: USO ACOTADO: consulta puntual sobre el subconjunto que lo necesita.
B52: Nomenclátor de facturación del SNS | C52: Mensual, por código nacional, con precios y agrupaciones homogéneas. | D52: Su alcance es la prestación farmacéutica por receta. Deja fuera buena parte de lo hospitalario y no aporta nada clínico de esta hoja. | E52: DESCARTADA para este uso.
B54: Recomendación
B55: 1. Migrad, no reconstruyáis | C55: 26 de los 33 campos salen de vuestro catálogo actual. Un proyecto planteado como 'poblar desde una base externa' invierte el esfuerzo y añade riesgo clínico donde no lo había.
B56: 2. CIMA para el único bloque que os falta | C56: Los excipientes son el hueco real, y CIMA lo cubre gratis, por API, con id estable y con cantidad. Cruce por CN → nregistro → excipientes, replicando en todas las presentaciones del registro.
B57: 3. No compréis base de datos por esta hoja | C57: BOT PLUS aporta sobre CIMA lo mismo en composición (los mismos excipientes de declaración obligatoria, de las mismas fichas técnicas). La decisión de licenciar debe tomarse mirando Transversales (interacciones, alergias, enfermedades) y las dosis máximas del Principio Activo, no la Especialidad.
B58: 4. Acotad la curación manual | C58: Validez tras apertura y multidosis no están codificados en ninguna fuente. Priorizad: refrigerados, viales multidosis, reconstituidos y colirios. Todo lo demás puede quedar vacío sin pérdida clínica.
B59: 5. Poned el mantenimiento en el plan desde el día uno | C59: registroCambios de CIMA avisa de altas, bajas y modificaciones por fecha, indicando si cambió la ficha técnica, el estado o la comercialización. Sin esto, la carga nace caducando.

Sheet Eval. solo Ficha Técnica
A1: TODO EL MODELO EVALUADO CONTRA UNA SOLA FUENTE: EL TEXTO DE LA FICHA TÉCNICA
A2: Sin CIMA como API, sin catálogo propio, sin base comercial. Solo las secciones 1 a 10 del documento autorizado. Se evalúan los 353 campos conservados de las cuatro entidades.
A4: Nº | B4: Entidad | C4: Bloque origen | D4: Campo | E4: Tipo | F4: Obl. | G4: ¿Desde la FT? | H4: Sección FT | I4: Comentario
A5: 1 | B5: 1. Principio Activo | C5: Principio activo - General+DMAX | D5: IDPRINACT | E5: ENTERO | F5: N* | G5: No | H5: — | I5: Identificador interno o de vuestros maestros: fuera del alcance de una ficha técnica.
A6: 2 | B6: 1. Principio Activo | C6: Principio activo - General+DMAX | D6: IDEXTERNO | E6: CHAR(20) | F6: N* | G6: No | H6: — | I6: Identificador interno o de vuestros maestros: fuera del alcance de una ficha técnica.
A7: 3 | B7: 1. Principio Activo | C7: Principio activo - General+DMAX | D7: ALTID | E7: CHAR(50) | F7: N* | G7: Sí – directo | H7: 5.1 | I7: Si usáis el ATC como identificador alternativo, como en el ejemplo.
A8: 4 | B8: 1. Principio Activo | C8: Principio activo - General+DMAX | D8: DESCRIPCION | E8: CHAR(50) | F8: S* | G8: Sí – directo | H8: 2 | I8: Nombre del principio activo.
A9: 5 | B9: 1. Principio Activo | C9: Principio activo - General+DMAX | D9: ATC | E9: CHAR(50) | F9: N | G9: Sí – directo | H9: 5.1 | I9: La FT declara el código ATC de forma explícita.
A10: 6 | B10: 1. Principio Activo | C10: Principio activo - General+DMAX | D10: RECOMENPRESCRIP | E10: CHAR(4000) | F10: N | G10: Sí – directo | H10: 4.2 + 4.3 | I10: El mejor encaje de todo el modelo: es literalmente posología más contraindicaciones, que es lo que contiene el ejemplo del fichero.
A11: 7 | B11: 1. Principio Activo | C11: Principio activo - General+DMAX | D11: CITOSTATICO | E11: CHAR(1) | F11: S | G11: Parcial | H11: 5.1 / 6.6 | I11: Se deduce del ATC (grupo L01) y de las precauciones de manipulación de citotóxicos.
A12: 8 | B12: 1. Principio Activo | C12: Principio activo - General+DMAX | D12: ACTIVO | E12: CHAR(1) | F12: S | G12: No | H12: — | I12: Identificador interno o de vuestros maestros: fuera del alcance de una ficha técnica.
A13: 9 | B13: 1. Principio Activo | C13: Principio activo - General+DMAX | D13: GT_IDGRUPTERA | E13: ENTERO | F13: N* | G13: No | H13: — | I13: Identificador interno o de vuestros maestros: fuera del alcance de una ficha técnica.
A14: 10 | B14: 1. Principio Activo | C14: Principio activo - General+DMAX | D14: GT_IDEXTERNO | E14: CHAR(20) | F14: N* | G14: No | H14: — | I14: Identificador interno o de vuestros maestros: fuera del alcance de una ficha técnica.
A15: 11 | B15: 1. Principio Activo | C15: Principio activo - General+DMAX | D15: GT_CODIGO | E15: CHAR(20) | F15: N* | G15: Sí – directo | H15: 5.1 | I15: Nivel 4 del ATC.
A16: 12 | B16: 1. Principio Activo | C16: Principio activo - General+DMAX | D16: GT_ALTID | E16: CHAR(20) | F16: N* | G16: No | H16: — | I16: Identificador interno o de vuestros maestros: fuera del alcance de una ficha técnica.
... A117: 113 | B117: 1. Principio Activo | C117: Principio activo - Consejos | D117: VIA_IDEXTERNO | E117: CHAR(20) | F117: N* | G117: No | H117: — | I117: Identificador interno o de vuestros maestros: fuera del alcance de una ficha técnica.
A118: 114 | B118: 1. Principio Activo | C118: Principio activo - Consejos | D118: VIA_CODIGO | E118: CHAR(20) | F118: N* | G118: Sí – directo | H118: 4.2
A119: 115 | B119: 1. Principio Activo | C119: Principio activo - Consejos | D119: VIA_ALTID | E119: CHAR(20) | F119: N* | G119: No | H119: — | I119: Identificador interno o de vuestros maestros: fuera del alcance de una ficha técnica.
A120: 116 | B120: 1. Principio Activo | C120: Principio activo - Consejos | D120: FF_FORMAFAR | E120: ENTERO | F120: N* | G120: No | H120: — | I120: Sin correspondencia en el documento.
A121: 117 | B121: 1. Principio Activo | C121: Principio activo - Consejos | D121: FF_IDEXTERNO | E121: CHAR(20) | F121: N* | G121: No | H121: — | I121: Identificador interno o de vuestros maestros: fuera del alcance de una ficha técnica.
A122: 118 | B122: 1. Principio Activo | C122: Principio activo - Consejos | D122: FF_CODIGO | E122: CHAR(20) | F122: N* | G122: Sí – directo | H122: 3
A123: 119 | B123: 1. Principio Activo | C123: Principio activo - Consejos | D123: FF_ALTID | E123: CHAR(20) | F123: N* | G123: No | H123: — | I123: Identificador interno o de vuestros maestros: fuera del alcance de una ficha técnica.
A124: 120 | B124: 1. Principio Activo | C124: Principio activo - Consejos | D124: INDICADANEONATO | E124: CHAR(1) | F124: S | G124: Sí – interpretación | H124: 4.2 | I124: Se deduce de las poblaciones para las que la FT autoriza el medicamento.
A125: 121 | B125: 1. Principio Activo | C125: Principio activo - Consejos | D125: INDICADALACTANTE | E125: CHAR(1) | F125: S | G125: Sí – interpretación | H125: 4.2 | I125: Se deduce de las poblaciones para las que la FT autoriza el medicamento.
A126: 122 | B126: 1. Principio Activo | C126: Principio activo - Consejos | D126: INDICADAPEDIATRICO | E126: CHAR(1) | F126: S | G126: Sí – interpretación | H126: 4.2 | I126: Se deduce de las poblaciones para las que la FT autoriza el medicamento.
A127: 123 | B127: 1. Principio Activo | C127: Principio activo - Consejos | D127: INDICADAADULTO | E127: CHAR(1) | F127: S | G127: Sí – interpretación | H127: 4.2 | I127: Se deduce de las poblaciones para las que la FT autoriza el medicamento.
A128: 124 | B128: 1. Principio Activo | C128: Principio activo - Consejos | D128: INDICADAGERIATRICO | E128: CHAR(1) | F128: S | G128: Sí – interpretación | H128: 4.2 | I128: Se deduce de las poblaciones para las que la FT autoriza el medicamento.
A129: 125 | B129: 1. Principio Activo | C129: Principio activo - Consejos | D129: OBSERVACIONES | E129: CHAR(255) | F129: S | G129: Sí – directo | H129: 4.2 + 6.6 + 6.3 | I129: Segundo mejor encaje: 'con el estómago vacío', 'diluir en 100 ml y pasar en 20-30 min', estabilidad tras dilución. Todo está, repartido en tres secciones.
A130: 126 | B130: 1. Principio Activo | C130: Principio activo - DAnaliticos | D130: IDPRINACT | E130: ENTERO | F130: N* | G130: No | H130: — | I130: Identificador interno o de vuestros maestros: fuera del alcance de una ficha técnica.
A131: 127 | B131: 1. Principio Activo | C131: Principio activo - DAnaliticos | D131: IDEXTERNO | E131: CHAR(20) | F131: N* | G131: No | H131: — | I131: Identificador interno o de vuestros maestros: fuera del alcance de una ficha técnica.
A132: 128 | B132: 1. Principio Activo | C132: Principio activo - DAnaliticos | D132: ALTID | E132: CHAR(50) | F132: N* | G132: Sí – directo | H132: 5.1 | I132: Si usáis el ATC como identificador alternativo, como en el ejemplo.
A133: 129 | B133: 1. Principio Activo | C133: Principio activo - DAnaliticos | D133: DESCRIPCION | E133: CHAR(50) | F133: S* | G133: Sí – directo | H133: 1 / 2 | I133: Nombre heredado de la entidad padre.
A134: 130 | B134: 1. Principio Activo | C134: Principio activo - DAnaliticos | D134: DA_IDDATOANALITICO | E134: ENTERO | F134: N* | G134: No | H134: — | I134: Identificador interno o de vuestros maestros: fuera del alcance de una ficha técnica.
... A141: 137 | B141: 1. Principio Activo | C141: Principio activo - DAnaliticos | D141: OBSERVACIONES | E141: CHAR(255) | F141: N | G141: Parcial | H141: 4.4 | I141: El texto de la advertencia sí está; el umbral no.
A142: 138 | B142: 1. Principio Activo | C142: Principio activo - DAnaliticos | D142: APLICANEONATO | E142: CHAR(1) | F142: S | G142: Parcial | H142: 4.4
A143: 139 | B143: 1. Principio Activo | C143: Principio activo - DAnaliticos | D143: APLICALACTANTE | E143: CHAR(1) | F143: S | G143: Parcial | H143: 4.4
A144: 140 | B144: 1. Principio Activo | C144: Principio activo - DAnaliticos | D144: APLICAPEDIATRICO | E144: CHAR(1) | F144: S | G144: Parcial | H144: 4.4
A145: 141 | B145: 1. Principio Activo | C145: Principio activo - DAnaliticos | D145: APLICAADULTO | E145: CHAR(1) | F145: S | G145: Parcial | H145: 4.4
A146: 142 | B146: 1. Principio Activo | C146: Principio activo - DAnaliticos | D146: APLICAGERIATRICO | E146: CHAR(1) | F146: S | G146: Parcial | H146: 4.4
A147: 143 | B147: 1. Principio Activo | C147: Principio activo - DAnaliticos | D147: ACTIVO | E147: CHAR(1) | F147: S | G147: No | H147: — | I147: Identificador interno o de vuestros maestros: fuera del alcance de una ficha técnica.
...

Sheet Estimación de esfuerzo
A1: ESTIMACIÓN DE ESFUERZO FARMACÉUTICO
A2: Revisión manual de lo extraído + introducción de los campos que requieren interpretación. EXCLUYE interacciones.
A4: PARÁMETROS DE ENTRADA | C4: A - SERGAS | D4: B - Todo | E4: Nota
A5: Nº de principios activos en guía | C5: 1000 | D5: 7910 | E5: Incluye algún excipiente
A6: Nº de medicamentos prescribibles | C6: 2500 | D6: 6343
A7: Nº de especialidades (envases con CN) | C7: 4000 | D7: 29851
A8: % de PA complejos / alto riesgo | C8: 0.15 | D8: 0.15 | E8: Citostáticos, anticoagulantes, aminoglucósidos, opioides, insulinas, electrolitos concentrados.
A9: % de PA estándar | C9: 0.5 | D9: 0.5
A10: % de PA simples | C10: 0.35 | D10: 0.35
A11: Minutos por PA complejo | C11: 90 | D11: 90 | E11: Dosis máximas por 5 grupos poblacionales, consejos por vía, monitorización analítica, doble lectura.
A12: Minutos por PA estándar | C12: 25 | D12: 25 | E12: solo identificación, vías, frecuencias y recomendaciones; sin completar el bloque DMAX completo.
A13: Minutos por PA simple | C13: 10 | D13: 10
A14: Minutos por medicamento | C14: 12 | D14: 12 | E14: Incluye la hoja Info prescripción: 5 filas por medicamento, una por grupo poblacional.
A15: Minutos por especialidad (media) | C15: 2 | D15: 2 | E15: Solo multidosis y validez tras apertura, y solo en el 15-20% de envases donde aplica.
A16: Horas de construcción de maestros | C16: 0 | D16: 0 | E16: Excipientes, unidades, alergias, intolerancias, enfermedades y estados de riesgo. Coste único, no por registro.
A17: % de revisión cruzada (segundo lector) | C17: 0 | D17: 0 | E17: Opcional
A18: % de coordinación, reuniones y correcciones | C18: 0 | D18: 0 | E18: Opcional
A19: Coste/hora de farmacéutico (€, coste empresa) | C19: 40 | D19: 40
A20: Horas productivas por FTE y año | C20: 1760 | D20: 1760 | E20: Jornada anual
A21: Comprobación: los tres % de PA deben sumar 100% | C21: =SUM(C8:C10) -> 1 | D21: =SUM(D8:D10) -> 1
A23: CÁLCULO
A24: Horas · Principio Activo | C24: =C5*(C8*C11+C9*C12+C10*C13)/60 -> 491.66667 | D24: =D5*(D8*D11+D9*D12+D10*D13)/60 -> 3889.0833
A25: Horas · Medicamento | C25: =C6*C14/60 -> 500 | D25: =D6*D14/60 -> 1268.6
A26: Horas · Especialidad | C26: =C7*C15/60 -> 133.33333 | D26: =D7*D15/60 -> 995.03333
A27: Horas · Maestros transversales | C27: =C16 -> 0 | D27: =D16 -> 0
A28: Subtotal horas | C28: =SUM(C24:C27) -> 1125 | D28: =SUM(D24:D27) -> 6152.7167
A29: Horas · revisión cruzada | C29: =C28*C17 -> 0 | D29: =D28*D17 -> 0
A30: Horas · coordinación | C30: =C28*C18 -> 0 | D30: =D28*D18 -> 0
A31: TOTAL HORAS DE FARMACÉUTICO | C31: =C28+C29+C30 -> 1125 | D31: =D28+D29+D30 -> 6152.7167
A32: Coste estimado (€) | C32: =C31*C19 -> 45000 | D32: =D31*D19 -> 246108.67
A33: Equivalente en FTE-año | C33: =C31/C20 -> 0.63920455 | D33: =D31/D20 -> 3.4958617
A35: CALENDARIO (meses de trabajo)
A36: 1 farmacéutico a dedicación plena | C36: =C31/(C20/12) -> 7.6704545 | D36: =D31/(D20/12) -> 41.950341
A37: 2 farmacéuticos a dedicación plena | C37: =C31/(2*C20/12) -> 3.8352273 | D37: =D31/(2*D20/12) -> 20.97517

Sheet 4. Transversales
A1: TRANSVERSALES — campos clínicos
A2: Maestros y reglas de alerta que cruzan las tres entidades: grupo terapéutico, alergias, intolerancias, patologías, estados de riesgo e interacciones.
A4: Nº | B4: Categoría | C4: Bloque / Tabla origen | D4: Sección | E4: Sub-bloque | F4: Campo | G4: Tipo | H4: Obl. | I4: Descripción | J4: Notas
A5: Grupo Terapéutico
A6: 1 | B6: Clave | C6: Grupo Terapéutico | D6: IDENTIFICACIÓN | F6: IDGRUPTERA | G6: ENTERO | H6: N* | I6: Identificador interno del registro.
A7: 2 | B7: Clave | C7: Grupo Terapéutico | D7: IDENTIFICACIÓN | F7: IDEXTERNO | G7: CHAR(20) | H7: N* | I7: Identificador del registro en la aplicación externa.
A8: 3 | B8: Clave | C8: Grupo Terapéutico | D8: IDENTIFICACIÓN | F8: CODIGO | G8: CHAR(20) | H8: S | I8: Código.
A9: 4 | B9: Clave | C9: Grupo Terapéutico | D9: IDENTIFICACIÓN | F9: ALTID | G9: CHAR(20) | H9: N* | I9: Id alternativo del registro.
A10: 5 | B10: Clínico | C10: Grupo Terapéutico | D10: DETALLES | F10: DESCRIPCION | G10: CHAR(100) | H10: S | I10: Descripción.
A11: 6 | B11: Técnico | C11: Grupo Terapéutico | D11: DETALLES | F11: ACTIVO | G11: CHAR(1) | H11: S | I11: Estado de la activación del registro. Valores posibles: “S”: Activo “N”: No activo
A12: Alergias
A13: 7 | B13: Clave | C13: Alergias | D13: IDENTIFICACIÓN | F13: IDALERGIA | G13: ENTERO | H13: N* | I13: Identificador interno del registro.
A14: 8 | B14: Clave | C14: Alergias | D14: IDENTIFICACIÓN | F14: IDEXTERNO | G14: CHAR(20) | H14: N* | I14: Identificador del registro en la aplicación externa.
A15: 9 | B15: Clave | C15: Alergias | D15: IDENTIFICACIÓN | F15: CODIGOPROPIO | G15: CHAR(20) | H15: S | I15: Código.
A16: 10 | B16: Clave | C16: Alergias | D16: IDENTIFICACIÓN | F16: ALTID | G16: CHAR(20) | H16: N* | I16: Id alternativo del registro.
A17: 11 | B17: Clínico | C17: Alergias | D17: DETALLES | F17: DESCRIPCION | G17: CHAR(50) | H17: S | I17: Descripción.
A18: 12 | B18: Clínico | C18: Alergias | D18: DETALLES | F18: DESCRIPCIONBREVE | G18: CHAR(50) | H18: N | I18: Descripción breve.
A19: 13 | B19: Clínico | C19: Alergias | D19: DETALLES | F19: TIPO | G19: CHAR(20) | H19: N | I19: Tipo de alergia (texto libre)
A20: 14 | B20: Clínico | C20: Alergias | D20: DETALLES | F20: CODIGOSNOMED | G20: CHAR(20) | H20: N | I20: Código SNOMED.
A21: 15 | B21: Clínico | C21: Alergias | D21: DETALLES | F21: CODIGOATC | G21: CHAR(20) | H21: N | I21: Código ATC.
A22: 16 | B22: Clínico | C22: Alergias | D22: DETALLES | F22: CODIGOCIM10 | G22: CHAR(20) | H22: N | I22: Código CIM10.
A23: 17 | B23: Técnico | C23: Alergias | D23: DETALLES | F23: ACTIVO | G23: CHAR(1) | H23: S | I23: Estado de la activación del registro. Valores posibles: “S”: Activo “N”: No activo
A24: Enf.Congénita
A25: 18 | B25: Clave | C25: Enf.Congénita | D25: IDENTIFICACIÓN | F25: IDENFCONGEN | G25: ENTERO | H25: N* | I25: Identificador interno del registro.
A26: 19 | B26: Clave | C26: Enf.Congénita | D26: IDENTIFICACIÓN | F26: IDEXTERNO | G26: CHAR(20) | H26: N* | I26: Identificador del registro en la aplicación externa.
A27: 20 | B27: Clave | C27: Enf.Congénita | D27: IDENTIFICACIÓN | F27: CODIGO | G27: CHAR(20) | H27: S | I27: Código.
A28: 21 | B28: Clave | C28: Enf.Congénita | D28: IDENTIFICACIÓN | F28: ALTID | G28: CHAR(20) | H28: N* | I28: Id alternativo del registro.
A29: 22 | B29: Clínico | C29: Enf.Congénita | D29: DETALLES | F29: DESCRIPCION | G29: CHAR(50) | H29: S | I29: Descripción.
A30: 23 | B30: Técnico | C30: Enf.Congénita | D30: DETALLES | F30: ACTIVO | G30: CHAR(1) | H30: S | I30: Estado de la activación del registro. Valores posibles: “S”: Activo “N”: No activo
A31: Enf.Crónica
A32: 24 | B32: Clave | C32: Enf.Crónica | D32: IDENTIFICACIÓN | F32: IDENFCRONI | G32: ENTERO | H32: N* | I32: Identificador interno del registro.
A33: 25 | B33: Clave | C33: Enf.Crónica | D33: IDENTIFICACIÓN | F33: IDEXTERNO | G33: CHAR(20) | H33: N* | I33: Identificador del registro en la aplicación externa.
A34: 26 | B34: Clave | C34: Enf.Crónica | D34: IDENTIFICACIÓN | F34: CODIGO | G34: CHAR(20) | H34: S | I34: Código.
A35: 27 | B35: Clave | C35: Enf.Crónica | D35: IDENTIFICACIÓN | F35: ALTID | G35: CHAR(20) | H35: N* | I35: Id alternativo del registro.
A36: 28 | B36: Clínico | C36: Enf.Crónica | D36: DETALLES | F36: DESCRIPCION | G36: CHAR(50) | H36: S | I36: Descripción.
A37: 29 | B37: Técnico | C37: Enf.Crónica | D37: DETALLES | F37: ACTIVO | G37: CHAR(1) | H37: S | I37: Estado de la activación del registro. Valores posibles: “S”: Activo “N”: No activo
A38: Est. Riesgo
A39: 30 | B39: Clave | C39: Est. Riesgo | D39: IDENTIFICACIÓN | F39: IDESTRIESGO | G39: ENTERO | H39: N* | I39: Identificador interno del registro.
A40: 31 | B40: Clave | C40: Est. Riesgo | D40: IDENTIFICACIÓN | F40: IDEXTERNO | G40: CHAR(20) | H40: N* | I40: Identificador del registro en la aplicación externa.
A41: 32 | B41: Clave | C41: Est. Riesgo | D41: IDENTIFICACIÓN | F41: CODIGO | G41: CHAR(20) | H41: S | I41: Código.
...

Sheet Excluidos (gestión)
A1: CAMPOS EXCLUIDOS — gestión logística y económica
A2: Campos presentes en el fichero origen que se han apartado por ser de compras, almacén, dispensación, facturación o presentación. Se listan para que la exclusión sea revisable.
A4: Nº | B4: Categoría | C4: Bloque / Tabla origen | D4: Sección | E4: Sub-bloque | F4: Campo | G4: Tipo | H4: Obl. | I4: Descripción | J4: Notas
A5: Principio activo - General+DMAX
A6: 1 | B6: Gestión | C6: Principio activo - General+DMAX | D6: DETALLES | F6: DISPHDIAPRESCLIBRE | G6: CHAR(1) | H6: S | I6: Indica que la especialidad está disponible para la prescripción libre en HDIA. Valores posibles: “S”: Sí “N”: No
A7: 2 | B7: Gestión | C7: Principio activo - General+DMAX | D7: DETALLES | F7: RESERVA | G7: CHAR(5) | H7: N* | I7: Tiempo de reserva para el caso de prescripción libre HDIA. Valores posibles: tiempo entre 00:00 y 23:59 * (Obligatorio solo si DISPHDIAPRESCLBRE = 'S')
A8: 3 | B8: Gestión | C8: Principio activo - General+DMAX | D8: DETALLES | E8: CONDICIONES DE CONSERVACIÓN - OPCIONAL | F8: CC_IDCONDCONS | G8: ENTERO | H8: N* | I8: Identificador interno de la condición de conservación. | J8: Revisable: conservación es almacén, pero puede mostrarse al administrar.
A9: 4 | B9: Gestión | C9: Principio activo - General+DMAX | D9: DETALLES | E9: CONDICIONES DE CONSERVACIÓN - OPCIONAL | F9: CC_IDEXTERNO | G9: CHAR(20) | H9: N* | I9: Identificador de la condición de conservación.
A10: 5 | B10: Gestión | C10: Principio activo - General+DMAX | D10: DETALLES | E10: CONDICIONES DE CONSERVACIÓN - OPCIONAL | F10: CC_CODIGO | G10: CHAR(20) | H10: N* | I10: Código de la condición de conservación en la aplicación externa.
A11: 6 | B11: Gestión | C11: Principio activo - General+DMAX | D11: DETALLES | E11: CONDICIONES DE CONSERVACIÓN - OPCIONAL | F11: CC_ALTID | G11: CHAR(20) | H11: N* | I11: Identificador alternativo de la condición de conservación.
A12: 7 | B12: Gestión | C12: Principio activo - General+DMAX | D12: DETALLES | E12: TIPO DE ORDENACIÓN - OBLIGATORIO | F12: TO_IDTIPORDEN | G12: ENTERO | H12: N* | I12: Identificador interno del tipo de ordenación.
A13: 8 | B13: Gestión | C13: Principio activo - General+DMAX | D13: DETALLES | E13: TIPO DE ORDENACIÓN - OBLIGATORIO | F13: TO_IDEXTERNO | G13: CHAR(20) | H13: N* | I13: Identificador del tipo de ordenación en la aplicación externa.
A14: 9 | B14: Gestión | C14: Principio activo - General+DMAX | D14: DETALLES | E14: TIPO DE ORDENACIÓN - OBLIGATORIO | F14: TO_ORDENACION | G14: CHAR(20) | H14: N* | I14: Código del tipo de ordenación.
A15: 10 | B15: Gestión | C15: Principio activo - General+DMAX | D15: DETALLES | E15: TIPO DE ORDENACIÓN - OBLIGATORIO | F15: TO_ALTID | G15: CHAR(20) | H15: N* | I15: Identificador alternativo del tipo de ordenación.
A16: Medicamento - General
A17: 11 | B17: Gestión | C17: Medicamento - General | D17: DETALLES | F17: ENGUIA | G17: CHAR(1) | H17: S | I17: Indica si el medicamento está en guía. Valores posibles: "S": Sí. "N": No. | J17: Revisable: pertenencia a guía farmacoterapéutica (decisión de comisión, no dato clínico del fármaco).
A18: 12 | B18: Gestión | C18: Medicamento - General | D18: DETALLES | E18: CONDICIONES DE CONSERVACIÓN - OPCIONAL | F18: CC_IDCONDCONS | G18: ENTERO | H18: N* | I18: Identificador interno de la condición de conservación. | J18: Revisable: conservación es almacén, pero puede mostrarse al administrar.
A19: 13 | B19: Gestión | C19: Medicamento - General | D19: DETALLES | E19: CONDICIONES DE CONSERVACIÓN - OPCIONAL | F19: CC_IDEXTERNO | G19: CHAR(20) | H19: N* | I19: Identificador de la condición de conservación.
A20: 14 | B20: Gestión | C20: Medicamento - General | D20: DETALLES | E20: CONDICIONES DE CONSERVACIÓN - OPCIONAL | F20: CC_CODIGO | G20: CHAR(20) | H20: N* | I20: Código de la condición de conservación en la aplicación externa.
A21: 15 | B21: Gestión | C21: Medicamento - General | D21: DETALLES | E21: CONDICIONES DE CONSERVACIÓN - OPCIONAL | F21: CC_ALTID | G21: CHAR(20) | H21: N* | I21: Identificador alternativo de la condición de conservación.
A22: 16 | B22: Gestión | C22: Medicamento - General | D22: DETALLES | F22: DISPENSAR | G22: CHAR(1) | H22: S | I22: Indica si el medicamento se dispensa desde farmacia. Valores posibles: "S": Sí. "N": No.
A23: 17 | B23: Gestión | C23: Medicamento - General | D23: DETALLES | F23: DISPENSARIRMPCARRO | G23: CHAR(1) | H23: S | I23: Indica si el medicamento se dispensa por salidas de carro para medicación solicitada por IRMP. Valores posibles: "S": Sí. "N": No.
A24: 18 | B24: Gestión | C24: Medicamento - General | D24: DETALLES | F24: DISPINGRESO | G24: CHAR(1) | H24: S | I24: Indica que el medicamento está disponible para los circuitos de ingreso. Valores posibles: "S": Sí. "N": No.
A25: 19 | B25: Gestión | C25: Medicamento - General | D25: DETALLES | F25: DISPAMBU | G25: CHAR(1) | H25: S | I25: Indica que el medicamento está disponible para los circuitos de ambulatorio. Valores posibles: "S": Sí. "N": No.
